Workbook
Name Adm_Financeiro: 'Hard Skills'!$F$3:$F$8
Name Adm_Financeiro: 'Soft Skills'!$F$3:$F$8
Name Adm_Financeiro: Cargos!$E$2:$E$7
Name Civil: 'Hard Skills'!$A$3:$A$11
Name Civil: 'Soft Skills'!$A$3:$A$11
Name Civil: Cargos!$A$2:$A$10
Name Elétrica: 'Hard Skills'!$B$3:$B$16
Name Elétrica: 'Soft Skills'!$B$3:$B$15
Name Elétrica: Cargos!$B$2:$B$14
Name Eletromecânica: 'Hard Skills'!$D$3:$D$15
Name Eletromecânica: 'Soft Skills'!$D$3:$D$14
Name Eletromecânica: Cargos!$C$2:$C$13
Name Ger_Contratos: Cargos!$D$2

Sheet Aval Soft Skills
B2: 2024 / 2025 | C2: FICHA DE NIVELAMENTO - COMPETÊNCIAS COMPORTAMENTAIS
B4: Nome: | C4: Carla Leal Santos | D4: Critérios de avaliação: 1- Nunca / Quase nunca. Traço não evidente. 2- Poucas Vezes. Traço a ser desenvolvido. 3- Com Frequência. Traço a consolidar no estilo. 4- Quase Sempre.Traço marcante do estilo. 5- Profissional referência no aspecto. Reconhecido no meio.
B5: Área: | C5: Elétrica
B6: Cargo: | C6: Líder Técnico Área Elétrica ou Controle/Automação
B7: Gestor: | C7: Luiz Sérgio
B8: Data da Avaliação : | C8: ___ / ___ /2024
D9: CRITÉRIOS DE AVALIAÇÃO
C10: ASPECTOS AVALIADOS | D10: META | E10: AUTO - AVALIAÇÃO | F10: AVALIAÇÃO GESTOR | G10: OBSERVAÇÕES
C11: Visão de Negócios: É a capacidade de entender a Visão e Missão da INTEREST no contexto do mercado, relacionando fatores para formular estratégias e soluções que agreguem valor à organização. | D11: =VLOOKUP(C6,'Soft Skills'!A1:S47,2,0) -> N/A
C12: Liderança: Habilidade de promover um ambiente de cooperação, motivador e produtivo. Promove meios para o desenvolvimento dos colaboradores e seu próprio. Demonstra competência e habilidade em comunicar as mudanças, metas e expectativas. É exemplo e motiva-se com desafios.Sabe delegar quando necessário, contudo sem perder o controle. | D12: =VLOOKUP(C6,'Soft Skills'!A1:S47,3,0) -> 4
C13: Trabalho em Equipe: É a qualidade de trabalhar cooperativamente com outras pessoas em prol de objetivos comuns. Reconhece os papéis de cada em desempenha, respeitando a contribuição dos outros integrantes. Comunica-se com todos para trocar ideias e informações. | D13: =VLOOKUP(C6,'Soft Skills'!A1:S47,4,0) -> 4
C14: Foco em Resultado: Valoriza metas e objetivos bem definidos. Segue bons planos de ação, evitando distrações e obstáculos que afetam sua produtividade no dia a dia. Mantém-se focado naquilo que agrega mais valor (prazo e qualidade) às entregas finais aos clientes e ao negócio. | D14: =VLOOKUP(C6,'Soft Skills'!A1:S47,5,0) -> 4
C15: Iniciativa e Proatividade: É a faculdade de identificar e antecipar problemas ou oportunidades e tomar ações adequadas e ponderadas, visando o melhor resultado. Não foge, nem terceiriza o enfrentamento das situações que se apresentam. | D15: =VLOOKUP(C6,'Soft Skills'!A1:S47,6,0) -> N/A
C16: Inovação e Criatividade: É o talento de desenvolver soluções criativas e abordagens inovadoras e realistas para a solução de problemas ou para a melhoria contínua. Adapta-se a mudanças com rapidez, está sempre aberto a diferentes ideias. | D16: =VLOOKUP(C6,'Soft Skills'!A1:S47,7,0) -> N/A
C17: Organização: É a habilidade de colocar atividades e espaços em ordem para conseguir cumprir objetivos. Analisa dados e cenários, estabelece tarefas e ações, a exemplo de follow-ups de controle, para evitar desperdício de tempo e recursos. | D17: =VLOOKUP(C6,'Soft Skills'!A1:S47,8,0) -> N/A
C18: Relacionamento Interpessoal: É o condão de construir e manter um conjunto de relacionamentos internos e externos que contribuam para a realização dos objetivos da INTEREST. Dedica tempo e demostra genuíno interêsse por pessoas. | D18: =VLOOKUP(C6,'Soft Skills'!A1:S47,9,0) -> 4
C19: Comunicação: É o atributo de trocar informações com clareza, sejam elas informações técnicas, planos, estratégias, comportamentos até mesmo ideias e conceitos. Sabe se expressar e ouvir, reconhecendo as especificidades dos interlocutores, meios e situações. Certifica-se do correto entendimento de ambas as partes. | D19: =VLOOKUP(C6,'Soft Skills'!A1:S47,10,0) -> 4
C20: Raciocínio Lógico e Analítico: É a capacidade de compreender uma situação, identificando suas partes, estabelecendo relações, e analisando impactos de forma lógica e consistente. | D20: =VLOOKUP(C6,'Soft Skills'!A1:S47,11,0) -> N/A
C21: Administração de Conflitos: É a inteligência de facilitar o convívio entre as singularidades, com o intuito de transformá-las na força do time, e não na causa dos conflitos. Sabe escutar as partes na busca da solução justa, com firmeza, sem ser grosso e autoritário e com gentileza, sem ser passivo. | D21: =VLOOKUP(C6,'Soft Skills'!A1:S47,12,0) -> 4
C22: Interêsse por Conhecimento: Possui aqui um sentido mais restrito e visa especificamente o estagiário. Refere-se ao interêsse demonstratado pelo mesmo pelos conhecimentos e pelas atividades oferecidos pela INTEREST. | D22: =VLOOKUP(C6,'Soft Skills'!A1:S47,13,0) -> N/A
C23: Autodesenvolvimento: Possui aqui um sentido restrito, visando os profissionais que superaram a fase inicial da crreira. Este, busca por iniciativa própria o desenvolvimento e assume a responsabilidade na conquista de novos conhecimentos/habilidades e formação de networking, visando a sua carreira profissional. | D23: =VLOOKUP(C6,'Soft Skills'!A1:S47,14,0) -> N/A
C24: Prática de Trabalho Seguro: Coloca a saúde e a segurança no trabalho, assim como o respeito ao meio ambiente como valores absolutos. Conhece e pratica a Política de SSMA da INTEREST. | D24: =VLOOKUP(C6,'Soft Skills'!A1:S47,15,0) -> N/A
C25: Trabalho com Equipes Multidiciplinares: Esta competência, também deve ser entendida num sentido mais restrito e visa especificamente o Engenheiro IV. Por estar no último degrau antes uma posição de gestão, o profissional deve desenvolver conhecimentos e consolidar networking, para atuar através das disciplinas com competência e desenvoltura. | D25: =VLOOKUP(C6,'Soft Skills'!A1:S47,16,0) -> N/A
C26: Visão Espacial: Esta competência deve, igualmente, ser entendida num sentido mais restrito e visa especificamente o Cadista.Trata-se do dom de perceber mentalmente e comunicar formas espaciais a partir de desenhos representativos em duas dimensões. | D26: =VLOOKUP(C6,'Soft Skills'!A1:S47,17,0) -> N/A
C27: Precisão: Esta competência deve ser entendida num sentido restrito e visa especificamente o profissional da Diretoria Administrativa-Finaceira. É a virtude de ser rigoroso com registros contábeis e financeiros que exigem exatidão dos números. | D27: =VLOOKUP(C6,'Soft Skills'!A1:S47,18,0) -> N/A
C28: Discrição: Da mesma forma, esta competência deve ser entendida num sentido restrito e visa especificamente o profissional da Diretoria Administrativa-Finaceira. É a qualidade de ser reservado com as informações contábeis e pessoais dos colaboradores visando a preservação da confidencialidade das informações sensíveis. | D28: =VLOOKUP(C6,'Soft Skills'!A1:S47,19,0) -> N/A
C29: MÉDIAS | D29: =AVERAGE(D11:D28) -> 4 | E29: =AVERAGE(E11:E28) -> #DIV/0! | F29: =AVERAGE(F11:F28) -> #DIV/0!
B31: Assinatura do Colaborador: | D31: Data Avaliação Conjunta | E31: ____ / ____ / ____ | F31: Assinatura do Gestor:

Sheet Aval Hard Skills
B2: 2023 / 2024 | C2: FICHA DE NIVELAMENTO - COMPETÊNCIAS TÉCNICAS
B4: Nome: | C4: ='Aval Soft Skills'!C4 -> Carla Leal Santos | D4: Critérios de avaliação: 1- Em desenvolvimento. Ex. Auxiliar de Engenharia, Engenheiro 1, Técnico 1. 2- Executa com orientação e supervisão próximas. 3- Executa com autonomia. O seu trabalho necessita de verificação mais cuidadosa. 4- Executa plenamente e possui conhecimento para supervisionar e verificar outros. 5- Profissional referência sobre o assunto. Reconhecido no meio.
B5: Área: | C5: ='Aval Soft Skills'!C5 -> Elétrica
B6: Cargo: | C6: ='Aval Soft Skills'!C6 -> Líder Técnico Área Elétrica ou Controle/Automação
B7: Gestor: | C7: ='Aval Soft Skills'!C7 -> Luiz Sérgio
B8: Data da Avaliação : | C8: ='Aval Soft Skills'!C8 -> ___ / ___ /2024
D9: CRITÉRIOS DE AVALIAÇÃO
C10: ASPECTOS AVALIADOS | D10: META | E10: AUTO - AVALIAÇÃO | F10: AVALIAÇÃO GESTOR | G10: OBSERVAÇÕES
C11: =IF($C$5="Civil",VLOOKUP('Aval Hard Skills'!$C$5,'Hard Skills'!A1:U11,2,0),(IF($C$5="Elétrica",VLOOKUP('Aval Hard Skills'!$C$5,'Hard Skills'!A12:U26,2,0),(IF($C$5="Eletromecânica",VLOOKUP('Aval Hard Skills'!$C$5,'Hard Skills'!A27:U40,2,0),(IF($C$5="Ger_Contratos",VLOOKUP('Aval Hard Skills'!$C$5,'Hard Skills'!A41:U43,2,0),(IF($C$5="Adm_Financeiro",VLOOKUP('Aval Hard Skills'!C5,'Hard Skills'!A44:U51,2,)))))))))) -> Capacidade de analizar e identificar criterios, padrões e documentos de referencia. | D11: =VLOOKUP(C6,'Hard Skills'!A1:U51,2,0) -> 4
C12: =IF($C$5="Civil",VLOOKUP('Aval Hard Skills'!$C$5,'Hard Skills'!A1:U11,3,0),(IF($C$5="Elétrica",VLOOKUP('Aval Hard Skills'!$C$5,'Hard Skills'!A12:U26,3,0),(IF($C$5="Eletromecânica",VLOOKUP('Aval Hard Skills'!$C$5,'Hard Skills'!A27:U40,3,0),(IF($C$5="Ger_Contratos",VLOOKUP('Aval Hard Skills'!$C$5,'Hard Skills'!A41:U43,3,0),(IF($C$5="Adm_Financeiro",VLOOKUP('Aval Hard Skills'!C5,'Hard Skills'!A44:U51,3,)))))))))) -> Conhecimento dos principios dos sistemas de proteção, controle e supervisão de subestações | D12: =VLOOKUP(C6,'Hard Skills'!A1:U51,3,0) -> 4
C13: =IF($C$5="Civil",VLOOKUP('Aval Hard Skills'!$C$5,'Hard Skills'!A1:U11,4,0),(IF($C$5="Elétrica",VLOOKUP('Aval Hard Skills'!$C$5,'Hard Skills'!A12:U26,4,0),(IF($C$5="Eletromecânica",VLOOKUP('Aval Hard Skills'!$C$5,'Hard Skills'!A27:U40,4,0),(IF($C$5="Ger_Contratos",VLOOKUP('Aval Hard Skills'!$C$5,'Hard Skills'!A41:U43,4,0),(IF($C$5="Adm_Financeiro",VLOOKUP('Aval Hard Skills'!C5,'Hard Skills'!A44:U51,4,)))))))))) -> Capacidade de desenvolver projetos de MPCCSR (Funcional,logico,Fiação e interligação | D13: =VLOOKUP(C6,'Hard Skills'!A1:U51,4,0) -> 4
C14: =IF($C$5="Civil",VLOOKUP('Aval Hard Skills'!$C$5,'Hard Skills'!A1:U11,5,0),(IF($C$5="Elétrica",VLOOKUP('Aval Hard Skills'!$C$5,'Hard Skills'!A12:U26,5,0),(IF($C$5="Eletromecânica",VLOOKUP('Aval Hard Skills'!$C$5,'Hard Skills'!A27:U40,5,0),(IF($C$5="Ger_Contratos",VLOOKUP('Aval Hard Skills'!$C$5,'Hard Skills'!A41:U43,5,0),(IF($C$5="Adm_Financeiro",VLOOKUP('Aval Hard Skills'!C5,'Hard Skills'!A44:U51,5,)))))))))) -> Dominio na execução de projetos utilizando o cadgraph | D14: =VLOOKUP(C6,'Hard Skills'!A1:U51,5,0) -> 4
C15: =IF($C$5="Civil",VLOOKUP('Aval Hard Skills'!$C$5,'Hard Skills'!A1:U11,6,0),(IF($C$5="Elétrica",VLOOKUP('Aval Hard Skills'!$C$5,'Hard Skills'!A12:U26,6,0),(IF($C$5="Eletromecânica",VLOOKUP('Aval Hard Skills'!$C$5,'Hard Skills'!A27:U40,6,0),(IF($C$5="Ger_Contratos",VLOOKUP('Aval Hard Skills'!$C$5,'Hard Skills'!A41:U43,6,0),(IF($C$5="Adm_Financeiro",VLOOKUP('Aval Hard Skills'!C5,'Hard Skills'!A44:U51,6,)))))))))) -> Capacidade para desenvolver arquitetura do sistema digital | D15: =VLOOKUP(C6,'Hard Skills'!A1:U51,6,0) -> 4
C16: =IF($C$5="Civil",VLOOKUP('Aval Hard Skills'!$C$5,'Hard Skills'!A1:U11,7,0),(IF($C$5="Elétrica",VLOOKUP('Aval Hard Skills'!$C$5,'Hard Skills'!A12:U26,7,0),(IF($C$5="Eletromecânica",VLOOKUP('Aval Hard Skills'!$C$5,'Hard Skills'!A27:U40,7,0),(IF($C$5="Ger_Contratos",VLOOKUP('Aval Hard Skills'!$C$5,'Hard Skills'!A41:U43,7,0),(IF($C$5="Adm_Financeiro",VLOOKUP('Aval Hard Skills'!C5,'Hard Skills'!A44:U51,7,)))))))))) -> Capacidade de elaboração de lista de pontos | D16: =VLOOKUP(C6,'Hard Skills'!A1:U51,7,0) -> 4
C17: =IF($C$5="Civil",VLOOKUP('Aval Hard Skills'!$C$5,'Hard Skills'!A1:U11,8,0),(IF($C$5="Elétrica",VLOOKUP('Aval Hard Skills'!$C$5,'Hard Skills'!A12:U26,8,0),(IF($C$5="Eletromecânica",VLOOKUP('Aval Hard Skills'!$C$5,'Hard Skills'!A27:U40,8,0),(IF($C$5="Ger_Contratos",VLOOKUP('Aval Hard Skills'!$C$5,'Hard Skills'!A41:U43,8,0),(IF($C$5="Adm_Financeiro",VLOOKUP('Aval Hard Skills'!C5,'Hard Skills'!A44:U51,8,)))))))))) -> Dominio no desenvolvimento de base de dados e telas no SAGE | D17: =VLOOKUP(C6,'Hard Skills'!A1:U51,8,0) -> 4
C18: =IF($C$5="Civil",VLOOKUP('Aval Hard Skills'!$C$5,'Hard Skills'!A1:U11,9,0),(IF($C$5="Elétrica",VLOOKUP('Aval Hard Skills'!$C$5,'Hard Skills'!A12:U26,9,0),(IF($C$5="Eletromecânica",VLOOKUP('Aval Hard Skills'!$C$5,'Hard Skills'!A27:U40,9,0),(IF($C$5="Ger_Contratos",VLOOKUP('Aval Hard Skills'!$C$5,'Hard Skills'!A41:U43,9,0),(IF($C$5="Adm_Financeiro",VLOOKUP('Aval Hard Skills'!C5,'Hard Skills'!A44:U51,9,)))))))))) -> Dominio dos procedimentos de testes de nível 1 (TAF, TAC) | D18: =VLOOKUP(C6,'Hard Skills'!A1:U51,9,0) -> 4
C19: =IF($C$5="Civil",VLOOKUP('Aval Hard Skills'!$C$5,'Hard Skills'!A1:U11,10,0),(IF($C$5="Elétrica",VLOOKUP('Aval Hard Skills'!$C$5,'Hard Skills'!A12:U26,10,0),(IF($C$5="Eletromecânica",VLOOKUP('Aval Hard Skills'!$C$5,'Hard Skills'!A27:U40,10,0),(IF($C$5="Ger_Contratos",VLOOKUP('Aval Hard Skills'!$C$5,'Hard Skills'!A41:U43,10,0),(IF($C$5="Adm_Financeiro",VLOOKUP('Aval Hard Skills'!C5,'Hard Skills'!A44:U51,10,)))))))))) -> Dominio na integração da base de dados no TAF e TAC | D19: =VLOOKUP(C6,'Hard Skills'!A1:U51,10,0) -> 4
C20: =IF($C$5="Civil",VLOOKUP('Aval Hard Skills'!$C$5,'Hard Skills'!A1:U11,11,0),(IF($C$5="Elétrica",VLOOKUP('Aval Hard Skills'!$C$5,'Hard Skills'!A12:U26,11,0),(IF($C$5="Eletromecânica",VLOOKUP('Aval Hard Skills'!$C$5,'Hard Skills'!A27:U40,11,0),(IF($C$5="Ger_Contratos",VLOOKUP('Aval Hard Skills'!$C$5,'Hard Skills'!A41:U43,11,0),(IF($C$5="Adm_Financeiro",VLOOKUP('Aval Hard Skills'!C5,'Hard Skills'!A44:U51,11,)))))))))) -> Proj. Básico de MPCC | D20: =VLOOKUP(C6,'Hard Skills'!A1:U51,11,0) -> 4
C21: =IF($C$5="Civil",VLOOKUP('Aval Hard Skills'!$C$5,'Hard Skills'!A1:U11,12,0),(IF($C$5="Elétrica",VLOOKUP('Aval Hard Skills'!$C$5,'Hard Skills'!A12:U26,12,0),(IF($C$5="Eletromecânica",VLOOKUP('Aval Hard Skills'!$C$5,'Hard Skills'!A27:U40,12,0),(IF($C$5="Ger_Contratos",VLOOKUP('Aval Hard Skills'!$C$5,'Hard Skills'!A41:U43,12,0),(IF($C$5="Adm_Financeiro",VLOOKUP('Aval Hard Skills'!C5,'Hard Skills'!A44:U51,12,)))))))))) -> Proj. Básico de Serv. Aux. | D21: =VLOOKUP(C6,'Hard Skills'!A1:U51,12,0) -> 4
C22: =IF($C$5="Civil",VLOOKUP('Aval Hard Skills'!$C$5,'Hard Skills'!A1:U11,13,0),(IF($C$5="Elétrica",VLOOKUP('Aval Hard Skills'!$C$5,'Hard Skills'!A12:U26,13,0),(IF($C$5="Eletromecânica",VLOOKUP('Aval Hard Skills'!$C$5,'Hard Skills'!A27:U40,13,0),(IF($C$5="Ger_Contratos",VLOOKUP('Aval Hard Skills'!$C$5,'Hard Skills'!A41:U43,13,0),(IF($C$5="Adm_Financeiro",VLOOKUP('Aval Hard Skills'!C5,'Hard Skills'!A44:U51,13,)))))))))) -> M.C - Carregador /Retificadores | D22: =VLOOKUP(C6,'Hard Skills'!A1:U51,13,0) -> 4
C23: =IF($C$5="Civil",VLOOKUP('Aval Hard Skills'!$C$5,'Hard Skills'!A1:U11,14,0),(IF($C$5="Elétrica",VLOOKUP('Aval Hard Skills'!$C$5,'Hard Skills'!A12:U26,14,0),(IF($C$5="Eletromecânica",VLOOKUP('Aval Hard Skills'!$C$5,'Hard Skills'!A27:U40,14,0),(IF($C$5="Ger_Contratos",VLOOKUP('Aval Hard Skills'!$C$5,'Hard Skills'!A41:U43,14,0),(IF($C$5="Adm_Financeiro",VLOOKUP('Aval Hard Skills'!C5,'Hard Skills'!A44:U51,14,)))))))))) -> M.C - GMG | D23: =VLOOKUP(C6,'Hard Skills'!A1:U51,14,0) -> 4
C24: =IF($C$5="Civil",VLOOKUP('Aval Hard Skills'!$C$5,'Hard Skills'!A1:U11,15,0),(IF($C$5="Elétrica",VLOOKUP('Aval Hard Skills'!$C$5,'Hard Skills'!A12:U26,15,0),(IF($C$5="Eletromecânica",VLOOKUP('Aval Hard Skills'!$C$5,'Hard Skills'!A27:U40,15,0),(IF($C$5="Ger_Contratos",VLOOKUP('Aval Hard Skills'!$C$5,'Hard Skills'!A41:U43,15,0),(IF($C$5="Adm_Financeiro",VLOOKUP('Aval Hard Skills'!C5,'Hard Skills'!A44:U51,15,)))))))))) -> Dimens. Cabos e Disparadores | D24: =VLOOKUP(C6,'Hard Skills'!A1:U51,15,0) -> 4
C25: =IF($C$5="Civil",VLOOKUP('Aval Hard Skills'!$C$5,'Hard Skills'!A1:U11,16,0),(IF($C$5="Elétrica",VLOOKUP('Aval Hard Skills'!$C$5,'Hard Skills'!A12:U26,16,0),(IF($C$5="Eletromecânica",VLOOKUP('Aval Hard Skills'!$C$5,'Hard Skills'!A27:U40,16,0),(IF($C$5="Ger_Contratos",VLOOKUP('Aval Hard Skills'!$C$5,'Hard Skills'!A41:U43,16,0),(IF($C$5="Adm_Financeiro",VLOOKUP('Aval Hard Skills'!C5,'Hard Skills'!A44:U51,16,)))))))))) -> - | D25: =VLOOKUP(C6,'Hard Skills'!A1:U51,16,0) -> -
C26: =IF($C$5="Civil",VLOOKUP('Aval Hard Skills'!$C$5,'Hard Skills'!A1:U11,17,0),(IF($C$5="Elétrica",VLOOKUP('Aval Hard Skills'!$C$5,'Hard Skills'!A12:U26,17,0),(IF($C$5="Eletromecânica",VLOOKUP('Aval Hard Skills'!$C$5,'Hard Skills'!A27:U40,17,0),(IF($C$5="Ger_Contratos",VLOOKUP('Aval Hard Skills'!$C$5,'Hard Skills'!A41:U43,17,0),(IF($C$5="Adm_Financeiro",VLOOKUP('Aval Hard Skills'!C5,'Hard Skills'!A44:U51,17,)))))))))) -> - | D26: =VLOOKUP(C6,'Hard Skills'!A1:U51,17,0) -> -
C27: =IF($C$5="Civil",VLOOKUP('Aval Hard Skills'!$C$5,'Hard Skills'!A1:U11,18,0),(IF($C$5="Elétrica",VLOOKUP('Aval Hard Skills'!$C$5,'Hard Skills'!A12:U26,18,0),(IF($C$5="Eletromecânica",VLOOKUP('Aval Hard Skills'!$C$5,'Hard Skills'!A27:U40,18,0),(IF($C$5="Ger_Contratos",VLOOKUP('Aval Hard Skills'!$C$5,'Hard Skills'!A41:U43,18,0),(IF($C$5="Adm_Financeiro",VLOOKUP('Aval Hard Skills'!C5,'Hard Skills'!A44:U51,18,)))))))))) -> - | D27: =VLOOKUP(C6,'Hard Skills'!A1:U51,18,0) -> -
C28: =IF($C$5="Civil",VLOOKUP('Aval Hard Skills'!$C$5,'Hard Skills'!A1:U11,19,0),(IF($C$5="Elétrica",VLOOKUP('Aval Hard Skills'!$C$5,'Hard Skills'!A12:U26,19,0),(IF($C$5="Eletromecânica",VLOOKUP('Aval Hard Skills'!$C$5,'Hard Skills'!A27:U40,19,0),(IF($C$5="Ger_Contratos",VLOOKUP('Aval Hard Skills'!$C$5,'Hard Skills'!A41:U43,19,0),(IF($C$5="Adm_Financeiro",VLOOKUP('Aval Hard Skills'!C5,'Hard Skills'!A44:U51,19,)))))))))) -> - | D28: =VLOOKUP(C6,'Hard Skills'!A1:U51,19,0) -> -
C29: =IF($C$5="Civil",VLOOKUP('Aval Hard Skills'!$C$5,'Hard Skills'!A1:U11,20,0),(IF($C$5="Elétrica",VLOOKUP('Aval Hard Skills'!$C$5,'Hard Skills'!A12:U26,20,0),(IF($C$5="Eletromecânica",VLOOKUP('Aval Hard Skills'!$C$5,'Hard Skills'!A27:U40,20,0),(IF($C$5="Ger_Contratos",VLOOKUP('Aval Hard Skills'!$C$5,'Hard Skills'!A41:U43,20,0),(IF($C$5="Adm_Financeiro",VLOOKUP('Aval Hard Skills'!C5,'Hard Skills'!A44:U51,20,)))))))))) -> - | D29: =VLOOKUP(C6,'Hard Skills'!A1:U51,20,0) -> -
C30: MÉDIAS | D30: =AVERAGE(D12:D29) -> 4 | E30: =AVERAGE(E12:E29) -> #DIV/0! | F30: =AVERAGE(F12:F29) -> #DIV/0!
B32: Assinatura do Colaborador: | D32: Data Avaliação Conjunta | E32: ____ / ____ / ____ | F32: Assinatura do Gestor:

Sheet PDI
B2: 2023 / 2024 | C2: PDI
B4: Nome: | C4: ='Aval Soft Skills'!C4 -> Carla Leal Santos | D4: O PDI é um instrumento de planejamento que deve conter ações de desenvolvimento a serem realizadas pelo colaborador no próximo período. Ao construir o seu PDI, baseia-se na avaliação recebido pelo gestor, com foco nas principais lacunas de competências. Planeja-se, então, ações de desenvolvimento para o período máximo de um ano. As competências gerais (soft skills) e as competências técnicas (hard skills) avaliadas são aquelas estabelecidas na PCCR.
B5: Área: | C5: ='Aval Soft Skills'!C5 -> Elétrica
B6: Cargo: | C6: ='Aval Soft Skills'!C6 -> Líder Técnico Área Elétrica ou Controle/Automação
B7: Gestor: | C7: ='Aval Soft Skills'!C7 -> Luiz Sérgio
B8: Data da Avaliação : | C8: ='Aval Soft Skills'!C8 -> ___ / ___ /2024
C10: Se o seu desempenho foi considerado acima das expectativas, monte o seu PDI para: | D10: Se o seu desempenho foi considerado dentro das expectativas, monte o seu PDI para: | G10: Se o seu desempenho foi considerado abaixo das expectativas, monte o seu PDI para:
C11: Participar de novos e desafiadores projetos na função atual; | D11: Reforçar as competências essenciais para a sua função atual; | G11: Desenvolver as competências essenciais para a sua função atual;
C12: Compartilhar conhecimento e atuar como coach de outros profissionais; | D12: Buscar benchmarking, outras experiências "on-the-job"; | G12: Buscar feedback constante do gestor e da equipe;
C13: Incluir oportunidades de job-rotation ou participação em outros projetos na área; | D13: Participar de treinamentos associados às competências que necessitam aprimoramento. | G13: Participar de atividades "on-the-job" que auxiliam na melhoria de desempenho.
C14: Preparar competências para o próximo passo na carreira.
C17: PONTOS FORTES
C26: PONTOS A DESENVOLVER
B27: Ações de desenvolvimento
B30: Cursos / Treinamentos
B33: Auto estudo / leitura
C35: PLANO DE DESENVOLVIMENTO INDIVIDUAL
B36: Ações de desenvolvimento
B39: Cursos / Treinamentos
B42: Auto estudo / leitura
B45: Cadeia de ajuda / coaching / ações "on-the-job"
B48: Outros
B52: Assinatura do Gestor / Colaborador: | D52: Média Ponderada Geral | E52: =AVERAGE('Aval Soft Skills'!E31,'Aval Hard Skills'!E32) -> #DIV/0!

Sheet Follow-up
B2: 2023 / 2024 | C2: FOLLOW-UP
B4: Nome: | C4: ='Aval Soft Skills'!C4 -> Carla Leal Santos
B5: Área: | C5: ='Aval Soft Skills'!C5 -> Elétrica
B6: Cargo: | C6: ='Aval Soft Skills'!C6 -> Líder Técnico Área Elétrica ou Controle/Automação
B7: Gestor: | C7: ='Aval Soft Skills'!C7 -> Luiz Sérgio
B8: Data da Avaliação : | C8: ='Aval Soft Skills'!C8 -> ___ / ___ /2024
C10: AÇÕES | D10: FOLLOW-UP 1 DATA | E10: FOLLOW-UP 2 DATA | F10: FOLLOW-UP 3 DATA | G10: OBSERVAÇÕES
B43: Assinatura do Gestor: | D43: Assinatura do Funcionário:

Sheet Cargos
A1: Civil | B1: Elétrica | C1: Eletromecânica | D1: Ger_Contratos | E1: Adm_Financeiro
A2: Gerente de Área Civil | B2: Gerente de Área SPCS | C2: Gerente de Área - Eletromecânica | D2: Gerente de Contratos | E2: Gerente Administrativo-Financeiro
A3: Líder Técnico - Área Civil | B3: Líder Técnico Área Elétrica ou Controle/Automação | C3: Líder Técnico – Área Eletromecânica | E3: Analista de RH
A4: Engenheiro Civil I | B4: Engenheiro Eletricista ou Controle/Automação I | C4: Engenheiro Eletromecânico I | E4: Assistente Administrativo-Financeiro
A5: Engenheiro Civil II | B5: Engenheiro Eletricista ou Controle/Automação II | C5: Engenheiro Eletromecânico II | E5: Assistente de Controladoria
A6: Engenheiro Civil III | B6: Engenheiro Eletricista ou Controle/Automação III | C6: Engenheiro Eletromecânico III | E6: Auxiliar Administrativo
A7: Engenheiro Civil IV | B7: Engenheiro Eletricista ou Controle/Automação IV | C7: Engenheiro Eletromecânico IV | E7: Auxiliar de Expedição
A8: Estagiário Engenharia Civil I | B8: Técnico Eletrotécnico I | C8: Técnico Eletromecânico I
A9: Estagiário Engenharia Civil II | B9: Técnico Eletrotécnico II | C9: Técnico Eletromecânico II
A10: Estagiário Técnico em Edificações | B10: Técnico Eletrotécnico III | C10: Técnico Eletromecânico III
B11: Técnico Eletrotécnico IV | C11: Técnico Eletromecânico IV
B12: Estagiário Engenharia Elétrica ou Controle/Automação I | C12: Auxiliar de Engenharia
B13: Estagiário Engenharia Elétrica ou Controle/Automação II | C13: Cadista
B14: Estagiário Técnico Eletrotécnico ou Controle/Automação

Sheet Soft Skills
B1: Visão de Negócios | C1: Liderança | D1: Trabalho de equipe | E1: Foco em Resultados | F1: Iniciativa e Proatividade | G1: Inovação e Criatividade | H1: Organização | I1: Relacionamento Interpessoal | J1: Comunicação | K1: Raciocínio lógico e analítico | L1: Administração de Conflitos | M1: Interesse por Conhecimento | N1: Auto- desenvolvimento | O1: Prática Trabalho Seguro | P1: Trabalho com Equipes Multidiciplinares | Q1: Visão Espacial | R1: Precisão | S1: Discrição | T1: Critérios de avaliação: 1- Nunca / Quase nunca. Traço não evidente. 2- Poucas Vezes. Traço a ser desenvolvido. 3- Com Frequência. Traço a consolidar no estilo. 4- Quase Sempre.Traço marcante do estilo. 5- Profissional referência no aspecto. Reconhecido no meio.
A2: Civil
A3: Gerente de Área Civil | B3: 5 | C3: 5 | D3: N/A | E3: 5 | F3: N/A | G3: N/A | H3: N/A | I3: N/A | J3: 5 | K3: N/A | L3: 5 | M3: N/A | N3: N/A | O3: N/A | P3: 5 | Q3: N/A | R3: N/A | S3: N/A
A4: Líder Técnico - Área Civil | B4: N/A | C4: 4 | D4: 4 | E4: 4 | F4: N/A | G4: N/A | H4: N/A | I4: 4 | J4: 4 | K4: N/A | L4: 4 | M4: N/A | N4: N/A | O4: N/A | P4: N/A | Q4: N/A | R4: N/A | S4: N/A
A5: Engenheiro Civil I | B5: N/A | C5: N/A | D5: 4 | E5: N/A | F5: 4 | G5: N/A | H5: 4 | I5: N/A | J5: 4 | K5: N/A | L5: N/A | M5: N/A | N5: 4 | O5: N/A | P5: N/A | Q5: N/A | R5: N/A | S5: N/A
A6: Engenheiro Civil II | B6: N/A | C6: N/A | D6: 4 | E6: N/A | F6: 4 | G6: N/A | H6: 4 | I6: N/A | J6: 4 | K6: N/A | L6: N/A | M6: N/A | N6: 4 | O6: N/A | P6: N/A | Q6: N/A | R6: N/A | S6: N/A
A7: Engenheiro Civil III | B7: N/A | C7: 4 | D7: 4 | E7: 4 | F7: N/A | G7: N/A | H7: N/A | I7: 4 | J7: 4 | K7: N/A | L7: 4 | M7: N/A | N7: N/A | O7: N/A | P7: N/A | Q7: N/A | R7: N/A | S7: N/A
A8: Engenheiro Civil IV | B8: N/A | C8: 4 | D8: 4 | E8: 4 | F8: N/A | G8: N/A | H8: N/A | I8: 4 | J8: 4 | K8: N/A | L8: 4 | M8: N/A | N8: N/A | O8: N/A | P8: N/A | Q8: N/A | R8: N/A | S8: N/A
A9: Estagiário Engenharia Civil I | B9: N/A | C9: N/A | D9: 4 | E9: N/A | F9: 4 | G9: N/A | H9: 4 | I9: N/A | J9: 4 | K9: N/A | L9: N/A | M9: N/A | N9: 4 | O9: N/A | P9: N/A | Q9: N/A | R9: N/A | S9: N/A
A10: Estagiário Engenharia Civil II | B10: N/A | C10: N/A | D10: 4 | E10: N/A | F10: 4 | G10: N/A | H10: 4 | I10: N/A | J10: 4 | K10: N/A | L10: N/A | M10: N/A | N10: 4 | O10: N/A | P10: N/A | Q10: N/A | R10: N/A | S10: N/A
A11: Estagiário Técnico em Edificações | B11: N/A | C11: N/A | D11: 4 | E11: N/A | F11: 4 | G11: N/A | H11: 4 | I11: N/A | J11: 4 | K11: N/A | L11: N/A | M11: N/A | N11: 4 | O11: N/A | P11: N/A | Q11: N/A | R11: N/A | S11: N/A
A12: Elétrica
A13: Gerente de Área SPCS | B13: 5 | C13: 5 | D13: N/A | E13: 5 | F13: N/A | G13: N/A | H13: N/A | I13: N/A | J13: 5 | K13: N/A | L13: 5 | M13: N/A | N13: N/A | O13: N/A | P13: 5 | Q13: N/A | R13: N/A | S13: N/A
A14: Líder Técnico Área Elétrica ou Controle/Automação | B14: N/A | C14: 4 | D14: 4 | E14: 4 | F14: N/A | G14: N/A | H14: N/A | I14: 4 | J14: 4 | K14: N/A | L14: 4 | M14: N/A | N14: N/A | O14: N/A | P14: N/A | Q14: N/A | R14: N/A | S14: N/A
A15: Engenheiro Eletricista ou Controle/Automação I | B15: N/A | C15: N/A | D15: 4 | E15: N/A | F15: 4 | G15: N/A | H15: 4 | I15: N/A | J15: 4 | K15: N/A | L15: N/A | M15: N/A | N15: 4 | O15: N/A | P15: N/A | Q15: N/A | R15: N/A | S15: N/A
A16: Engenheiro Eletricista ou Controle/Automação II | B16: N/A | C16: N/A | D16: 4 | E16: N/A | F16: 4 | G16: N/A | H16: 4 | I16: N/A | J16: 4 | K16: N/A | L16: N/A | M16: N/A | N16: 4 | O16: N/A | P16: N/A | Q16: N/A | R16: N/A | S16: N/A
A17: Engenheiro Eletricista ou Controle/Automação III | B17: N/A | C17: 4 | D17: 4 | E17: 4 | F17: N/A | G17: N/A | H17: N/A | I17: 4 | J17: 4 | K17: N/A | L17: 4 | M17: N/A | N17: N/A | O17: N/A | P17: N/A | Q17: N/A | R17: N/A | S17: N/A
A18: Engenheiro Eletricista ou Controle/Automação IV | B18: N/A | C18: 4 | D18: 4 | E18: 4 | F18: N/A | G18: N/A | H18: N/A | I18: 4 | J18: 4 | K18: N/A | L18: 4 | M18: N/A | N18: N/A | O18: N/A | P18: N/A | Q18: N/A | R18: N/A | S18: N/A
A19: Técnico Eletrotécnico I | B19: N/A | C19: N/A | D19: 4 | E19: N/A | F19: 4 | G19: N/A | H19: 4 | I19: N/A | J19: 4 | K19: N/A | L19: N/A | M19: N/A | N19: 4 | O19: N/A | P19: N/A | Q19: N/A | R19: N/A | S19: N/A
A20: Técnico Eletrotécnico II | B20: N/A | C20: N/A | D20: 4 | E20: N/A | F20: 4 | G20: N/A | H20: 4 | I20: N/A | J20: 4 | K20: N/A | L20: N/A | M20: N/A | N20: 4 | O20: N/A | P20: N/A | Q20: N/A | R20: N/A | S20: N/A
A21: Técnico Eletrotécnico III | B21: N/A | C21: N/A | D21: 4 | E21: N/A | F21: 4 | G21: N/A | H21: 4 | I21: N/A | J21: 4 | K21: N/A | L21: N/A | M21: N/A | N21: 4 | O21: N/A | P21: N/A | Q21: N/A | R21: N/A | S21: N/A
A22: Técnico Eletrotécnico IV | B22: N/A | C22: N/A | D22: 4 | E22: N/A | F22: 4 | G22: N/A | H22: 4 | I22: N/A | J22: 4 | K22: N/A | L22: N/A | M22: N/A | N22: 4 | O22: N/A | P22: N/A | Q22: N/A | R22: N/A | S22: N/A
A23: Estagiário Engenharia Elétrica ou Controle/Automação I | B23: N/A | C23: N/A | D23: 4 | E23: N/A | F23: 4 | G23: N/A | H23: 4 | I23: N/A | J23: 4 | K23: N/A | L23: N/A | M23: N/A | N23: 4 | O23: N/A | P23: N/A | Q23: N/A | R23: N/A | S23: N/A
A24: Estagiário Engenharia Elétrica ou Controle/Automação II | B24: N/A | C24: N/A | D24: 4 | E24: N/A | F24: 4 | G24: N/A | H24: 4 | I24: N/A | J24: 4 | K24: N/A | L24: N/A | M24: N/A | N24: 4 | O24: N/A | P24: N/A | Q24: N/A | R24: N/A | S24: N/A
A25: Estagiário Técnico Eletrotécnico ou Controle/Automação | B25: N/A | C25: N/A | D25: 4 | E25: N/A | F25: 4 | G25: N/A | H25: 4 | I25: N/A | J25: 4 | K25: N/A | L25: N/A | M25: N/A | N25: 4 | O25: N/A | P25: N/A | Q25: N/A | R25: N/A | S25: N/A
A26: Eletromecânica
A27: Gerente de Área - Eletromecânica | B27: 5 | C27: 5 | D27: N/A | E27: 5 | F27: N/A | G27: N/A | H27: N/A | I27: N/A | J27: 5 | K27: N/A | L27: 5 | M27: N/A | N27: N/A | O27: N/A | P27: 5 | Q27: N/A | R27: N/A | S27: N/A
A28: Líder Técnico – Área Eletromecânica | B28: N/A | C28: 4 | D28: 4 | E28: 4 | F28: N/A | G28: N/A | H28: N/A | I28: 4 | J28: 4 | K28: N/A | L28: 4 | M28: N/A | N28: N/A | O28: N/A | P28: N/A | Q28: N/A | R28: N/A | S28: N/A
A29: Engenheiro Eletromecânico I | B29: N/A | C29: N/A | D29: 4 | E29: N/A | F29: 4 | G29: N/A | H29: 4 | I29: N/A | J29: 4 | K29: N/A | L29: N/A | M29: N/A | N29: 4 | O29: N/A | P29: N/A | Q29: N/A | R29: N/A | S29: N/A
A30: Engenheiro Eletromecânico II | B30: N/A | C30: N/A | D30: 4 | E30: N/A | F30: 4 | G30: N/A | H30: 4 | I30: N/A | J30: 4 | K30: N/A | L30: N/A | M30: N/A | N30: 4 | O30: N/A | P30: N/A | Q30: N/A | R30: N/A | S30: N/A
A31: Engenheiro Eletromecânico III | B31: N/A | C31: 4 | D31: 4 | E31: 4 | F31: N/A | G31: N/A | H31: N/A | I31: 4 | J31: 4 | K31: N/A | L31: 4 | M31: N/A | N31: N/A | O31: N/A | P31: N/A | Q31: N/A | R31: N/A | S31: N/A
A32: Engenheiro Eletromecânico IV | B32: N/A | C32: 4 | D32: 4 | E32: 4 | F32: N/A | G32: N/A | H32: N/A | I32: 4 | J32: 4 | K32: N/A | L32: 4 | M32: N/A | N32: N/A | O32: N/A | P32: N/A | Q32: N/A | R32: N/A | S32: N/A
A33: Técnico Eletromecânico I | B33: N/A | C33: N/A | D33: 4 | E33: N/A | F33: 4 | G33: N/A | H33: 4 | I33: N/A | J33: 4 | K33: N/A | L33: N/A | M33: N/A | N33: 4 | O33: N/A | P33: N/A | Q33: N/A | R33: N/A | S33: N/A
A34: Técnico Eletromecânico II | B34: N/A | C34: N/A | D34: 4 | E34: N/A | F34: 4 | G34: N/A | H34: 4 | I34: N/A | J34: 4 | K34: N/A | L34: N/A | M34: N/A | N34: 4 | O34: N/A | P34: N/A | Q34: N/A | R34: N/A | S34: N/A
A35: Técnico Eletromecânico III | B35: N/A | C35: N/A | D35: 4 | E35: N/A | F35: 4 | G35: N/A | H35: 4 | I35: N/A | J35: 4 | K35: N/A | L35: N/A | M35: N/A | N35: 4 | O35: N/A | P35: N/A | Q35: N/A | R35: N/A | S35: N/A
A36: Técnico Eletromecânico IV | B36: N/A | C36: N/A | D36: 4 | E36: N/A | F36: 4 | G36: N/A | H36: 4 | I36: N/A | J36: 4 | K36: N/A | L36: N/A | M36: N/A | N36: 4 | O36: N/A | P36: N/A | Q36: N/A | R36: N/A | S36: N/A
A37: Auxiliar de Engenharia | B37: N/A | C37: N/A | D37: 4 | E37: N/A | F37: 4 | G37: N/A | H37: 4 | I37: N/A | J37: 4 | K37: N/A | L37: N/A | M37: N/A | N37: 4 | O37: N/A | P37: N/A | Q37: N/A | R37: N/A | S37: N/A
A38: Cadista | B38: N/A | C38: N/A | D38: 4 | E38: N/A | F38: 4 | G38: N/A | H38: 4 | I38: N/A | J38: 4 | K38: N/A | L38: N/A | M38: N/A | N38: 4 | O38: N/A | P38: N/A | Q38: N/A | R38: N/A | S38: N/A
A39: Ger_Contratos
A40: Gerente de Contratos | B40: 5 | C40: 5 | D40: N/A | E40: 5 | F40: N/A | G40: N/A | H40: N/A | I40: N/A | J40: 5 | K40: N/A | L40: 5 | M40: N/A | N40: N/A | O40: N/A | P40: 5 | Q40: N/A | R40: N/A | S40: N/A
...

Sheet Hard Skills
A1: Civil | B1: Capacidade de analisar e identificar critérios, padrões e doc. referência. | C1: Arquitetura - Planta, fachadas, cobertura e esquadrias. | D1: Terraplenagem e Especificação Técnica | E1: Locação de bases, canaletas e edificações | F1: Drenagem - Planta, detalhes, incluindo MC. | G1: Bacia de contenção e caixa separadora água e óleo, incluindo MC. | H1: Canaletas - Planta e detalhes. | I1: Bases e fundações de pórticos e equipamentos, incluindo MC. | J1: Fundações e estruturas de edificações, incluindo MC. | K1: Locação de sondagem, especificação de sondagem | L1: Instalações hidro-sanitárias. | M1: Projeto de Combate à Incêndio | N1: Urbanização - Acessos, cercas, alambrados, portões, incluindo MC de pavimento. | O1: Projeto de Aproveitamento de Água de Chuva | P1: Estruturas Metálicas | Q1: - | R1: - | S1: - | T1: - | U1: - | V1: Critérios de avaliação: 1- Em desenvolvimento. Ex. Estagiário ou trainee. 2- Executa com orientação e supervisão próximas. 3- Executa com autonomia. O seu trabalho necessita de verificação mais cuidadosa. 4- Executa plenamente e possui conhecimento para supervisionar e verificar outros. 5- Profissional referência sobre o assunto. Reconhecido no meio.
A3: Gerente de Área Civil | B3: 5 | C3: 5 | D3: 5 | E3: 5 | F3: 5 | G3: 5 | H3: 5 | I3: 5 | J3: 5 | K3: 5 | L3: 5 | M3: 5 | N3: 5 | O3: 5 | P3: 5 | Q3: - | R3: - | S3: - | T3: - | U3: -
A4: Líder Técnico - Área Civil | B4: 4 | C4: 4 | D4: 4 | E4: 4 | F4: 4 | G4: 4 | H4: 4 | I4: 4 | J4: 4 | K4: 4 | L4: 4 | M4: 4 | N4: 4 | O4: 4 | P4: 4 | Q4: - | R4: - | S4: - | T4: - | U4: -
A5: Engenheiro Civil I | B5: 2 | C5: 2 | D5: 2 | E5: 2 | F5: 2 | G5: 2 | H5: 2 | I5: 2 | J5: 2 | K5: 2 | L5: 2 | M5: 2 | N5: 2 | O5: 2 | P5: 2 | Q5: - | R5: - | S5: - | T5: - | U5: -
A6: Engenheiro Civil II | B6: 3 | C6: 3 | D6: 3 | E6: 3 | F6: 3 | G6: 3 | H6: 3 | I6: 3 | J6: 3 | K6: 3 | L6: 3 | M6: 3 | N6: 3 | O6: 3 | P6: 3 | Q6: - | R6: - | S6: - | T6: - | U6: -
A7: Engenheiro Civil III | B7: 4 | C7: 4 | D7: 4 | E7: 4 | F7: 4 | G7: 4 | H7: 4 | I7: 4 | J7: 4 | K7: 4 | L7: 4 | M7: 4 | N7: 4 | O7: 4 | P7: 4 | Q7: - | R7: - | S7: - | T7: - | U7: -
A8: Engenheiro Civil IV | B8: 4 | C8: 4 | D8: 4 | E8: 4 | F8: 4 | G8: 4 | H8: 4 | I8: 4 | J8: 4 | K8: 4 | L8: 4 | M8: 4 | N8: 4 | O8: 4 | P8: 4 | Q8: - | R8: - | S8: - | T8: - | U8: -
A9: Estagiário Engenharia Civil I | B9: 1 | C9: 1 | D9: 1 | E9: 1 | F9: 1 | G9: 1 | H9: 1 | I9: 1 | J9: 1 | K9: 1 | L9: 1 | M9: 1 | N9: 1 | O9: 1 | P9: 1 | Q9: - | R9: - | S9: - | T9: - | U9: -
A10: Estagiário Engenharia Civil II | B10: 2 | C10: 2 | D10: 2 | E10: 2 | F10: 2 | G10: 2 | H10: 2 | I10: 2 | J10: 2 | K10: 2 | L10: 2 | M10: 2 | N10: 2 | O10: 2 | P10: 2 | Q10: - | R10: - | S10: - | T10: - | U10: -
A11: Estagiário Técnico em Edificações | B11: 1 | C11: 1 | D11: 1 | E11: 1 | F11: 1 | G11: 1 | H11: 1 | I11: 1 | J11: 1 | K11: 1 | L11: 1 | M11: 1 | N11: 1 | O11: 1 | P11: 1 | Q11: - | R11: - | S11: - | T11: - | U11: -
A12: Elétrica | B12: Capacidade de analizar e identificar criterios, padrões e documentos de referencia. | C12: Conhecimento dos principios dos sistemas de proteção, controle e supervisão de subestações | D12: Capacidade de desenvolver projetos de MPCCSR (Funcional,logico,Fiação e interligação | E12: Dominio na execução de projetos utilizando o cadgraph | F12: Capacidade para desenvolver arquitetura do sistema digital | G12: Capacidade de elaboração de lista de pontos | H12: Dominio no desenvolvimento de base de dados e telas no SAGE | I12: Dominio dos procedimentos de testes de nível 1 (TAF, TAC) | J12: Dominio na integração da base de dados no TAF e TAC | K12: Proj. Básico de MPCC | L12: Proj. Básico de Serv. Aux. | M12: M.C - Carregador /Retificadores | N12: M.C - GMG | O12: Dimens. Cabos e Disparadores | P12: - | Q12: - | R12: - | S12: - | T12: - | U12: -
A14: Gerente de Área SPCS | B14: 5 | C14: 5 | D14: 5 | E14: 5 | F14: 5 | G14: 5 | H14: 5 | I14: 5 | J14: 5 | K14: 5 | L14: 5 | M14: 5 | N14: 5 | O14: 5 | P14: - | Q14: - | R14: - | S14: - | T14: - | U14: -
A15: Líder Técnico Área Elétrica ou Controle/Automação | B15: 4 | C15: 4 | D15: 4 | E15: 4 | F15: 4 | G15: 4 | H15: 4 | I15: 4 | J15: 4 | K15: 4 | L15: 4 | M15: 4 | N15: 4 | O15: 4 | P15: - | Q15: - | R15: - | S15: - | T15: - | U15: -
A16: Engenheiro Eletricista ou Controle/Automação I | B16: 2 | C16: 2 | D16: 2 | E16: 2 | F16: 2 | G16: 2 | H16: 2 | I16: 2 | J16: 2 | K16: 2 | L16: 2 | M16: 2 | N16: 2 | O16: 2 | P16: - | Q16: - | R16: - | S16: - | T16: - | U16: -
A17: Engenheiro Eletricista ou Controle/Automação II | B17: 3 | C17: 3 | D17: 3 | E17: 3 | F17: 3 | G17: 3 | H17: 3 | I17: 3 | J17: 3 | K17: 3 | L17: 3 | M17: 3 | N17: 3 | O17: 3 | P17: - | Q17: - | R17: - | S17: - | T17: - | U17: -
A18: Engenheiro Eletricista ou Controle/Automação III | B18: 4 | C18: 4 | D18: 4 | E18: 4 | F18: 4 | G18: 4 | H18: 4 | I18: 4 | J18: 4 | K18: 4 | L18: 4 | M18: 4 | N18: 4 | O18: 4 | P18: - | Q18: - | R18: - | S18: - | T18: - | U18: -
A19: Engenheiro Eletricista ou Controle/Automação IV | B19: 4 | C19: 4 | D19: 4 | E19: 4 | F19: 4 | G19: 4 | H19: 4 | I19: 4 | J19: 4 | K19: 4 | L19: 4 | M19: 4 | N19: 4 | O19: 4 | P19: - | Q19: - | R19: - | S19: - | T19: - | U19: -
A20: Técnico Eletrotécnico I | B20: 2 | C20: 2 | D20: 2 | E20: 2 | F20: 2 | G20: 2 | H20: 2 | I20: 2 | J20: 2 | K20: 2 | L20: 2 | M20: 2 | N20: 2 | O20: 2 | P20: - | Q20: - | R20: - | S20: - | T20: - | U20: -
A21: Técnico Eletrotécnico II | B21: 3 | C21: 3 | D21: 3 | E21: 3 | F21: 3 | G21: 3 | H21: 3 | I21: 3 | J21: 4 | K21: 3 | L21: 3 | M21: 3 | N21: 3 | O21: 3 | P21: - | Q21: - | R21: - | S21: - | T21: - | U21: -
A22: Técnico Eletrotécnico III | B22: 4 | C22: 4 | D22: 4 | E22: 4 | F22: 4 | G22: 4 | H22: 4 | I22: 4 | J22: 4 | K22: 4 | L22: 4 | M22: 4 | N22: 4 | O22: 4 | P22: - | Q22: - | R22: - | S22: - | T22: - | U22: -
A23: Técnico Eletrotécnico IV | B23: 4 | C23: 4 | D23: 4 | E23: 4 | F23: 4 | G23: 4 | H23: 4 | I23: 4 | J23: 4 | K23: 4 | L23: 4 | M23: 4 | N23: 4 | O23: 4 | P23: - | Q23: - | R23: - | S23: - | T23: - | U23: -
A24: Estagiário Engenharia Elétrica ou Controle/Automação I | B24: 1 | C24: 1 | D24: 1 | E24: 1 | F24: 1 | G24: 1 | H24: 1 | I24: 1 | J24: 1 | K24: 1 | L24: 1 | M24: 1 | N24: 1 | O24: 1 | P24: - | Q24: - | R24: - | S24: - | T24: - | U24: -
A25: Estagiário Engenharia Elétrica ou Controle/Automação II | B25: 2 | C25: 2 | D25: 2 | E25: 2 | F25: 2 | G25: 2 | H25: 2 | I25: 2 | J25: 2 | K25: 2 | L25: 2 | M25: 2 | N25: 2 | O25: 2 | P25: - | Q25: - | R25: - | S25: - | T25: - | U25: -
A26: Estagiário Técnico Eletrotécnico ou Controle/Automação | B26: 1 | C26: 1 | D26: 1 | E26: 1 | F26: 1 | G26: 1 | H26: 1 | I26: 1 | J26: 1 | K26: 1 | L26: 1 | M26: 1 | N26: 1 | O26: 1 | P26: - | Q26: - | R26: - | S26: - | T26: - | U26: -
A27: Eletromecânica | B27: Capacidade de analisar e identificar critérios, padrões e doc. referência. | C27: Unifilar Simplificado | D27: Planta de Situação e Localização | E27: Arranjo Físico - Planta e Cortes | F27: Dimensionamento de Barramento | G27: Lista de Material de Barramento | H27: Esticamento de Cabos, incluindo o relatório | I27: Cadeias e Fixação de Cabos Para-raios | J27: Eletrodutos e Canaletas - Planta e Detalhes, incluindo Lista de Material | K27: Detalhes de Instalação de Equipamentos de Pátio | L27: Requisitos de Estruturas (Planta, Cortes, Isométrico) | M27: Sistema de Proteção Atmosférica do Pátio e Edificações - Planta e Cortes, incluindo Memória de Cálculo | N27: Malha de Terra - Planta e Detalhes, incluindo Memória de Cálculo e Lista de Material | O27: Iluminação de Pátio - Planta, Quadros, incluindo Memória de Cálculo e Lista de Material | P27: Edificações - Intalações Elétricas, Incluindo Memória de Cálculo de Climatização e Lista de Material | Q27: - | R27: - | S27: - | T27: - | U27: -
A29: Gerente de Área - Eletromecânica | B29: 5 | C29: 5 | D29: 5 | E29: 5 | F29: 5 | G29: 5 | H29: 5 | I29: 5 | J29: 5 | K29: 5 | L29: 5 | M29: 5 | N29: 5 | O29: 5 | P29: 5 | Q29: - | R29: - | S29: - | T29: - | U29: -
A30: Líder Técnico – Área Eletromecânica | B30: 4 | C30: 4 | D30: 4 | E30: 4 | F30: 4 | G30: 4 | H30: 4 | I30: 4 | J30: 4 | K30: 4 | L30: 4 | M30: 4 | N30: 4 | O30: 4 | P30: 4 | Q30: - | R30: - | S30: - | T30: - | U30: -
A31: Engenheiro Eletromecânico I | B31: 2 | C31: 2 | D31: 2 | E31: 2 | F31: 2 | G31: 2 | H31: 2 | I31: 2 | J31: 2 | K31: 2 | L31: 2 | M31: 2 | N31: 2 | O31: 2 | P31: 2 | Q31: - | R31: - | S31: - | T31: - | U31: -
A32: Engenheiro Eletromecânico II | B32: 3 | C32: 3 | D32: 3 | E32: 3 | F32: 3 | G32: 3 | H32: 3 | I32: 3 | J32: 3 | K32: 3 | L32: 3 | M32: 3 | N32: 3 | O32: 3 | P32: 3 | Q32: - | R32: - | S32: - | T32: - | U32: -
A33: Engenheiro Eletromecânico III | B33: 4 | C33: 4 | D33: 4 | E33: 4 | F33: 4 | G33: 4 | H33: 4 | I33: 4 | J33: 4 | K33: 4 | L33: 4 | M33: 4 | N33: 4 | O33: 4 | P33: 4 | Q33: - | R33: - | S33: - | T33: - | U33: -
A34: Engenheiro Eletromecânico IV | B34: 4 | C34: 4 | D34: 4 | E34: 4 | F34: 4 | G34: 4 | H34: 4 | I34: 4 | J34: 4 | K34: 4 | L34: 4 | M34: 4 | N34: 4 | O34: 4 | P34: 4 | Q34: - | R34: - | S34: - | T34: - | U34: -
A35: Técnico Eletromecânico I | B35: 2 | C35: 2 | D35: 2 | E35: 2 | F35: 2 | G35: 2 | H35: 2 | I35: 2 | J35: 2 | K35: 2 | L35: 2 | M35: 2 | N35: 2 | O35: 2 | P35: 2 | Q35: - | R35: - | S35: - | T35: - | U35: -
A36: Técnico Eletromecânico II | B36: 3 | C36: 3 | D36: 3 | E36: 3 | F36: 3 | G36: 3 | H36: 3 | I36: 3 | J36: 4 | K36: 3 | L36: 3 | M36: 3 | N36: 3 | O36: 3 | P36: 3 | Q36: - | R36: - | S36: - | T36: - | U36: -
A37: Técnico Eletromecânico III | B37: 4 | C37: 4 | D37: 4 | E37: 4 | F37: 4 | G37: 4 | H37: 4 | I37: 4 | J37: 4 | K37: 4 | L37: 4 | M37: 4 | N37: 4 | O37: 4 | P37: 4 | Q37: - | R37: - | S37: - | T37: - | U37: -
A38: Técnico Eletromecânico IV | B38: 4 | C38: 4 | D38: 4 | E38: 4 | F38: 4 | G38: 4 | H38: 4 | I38: 4 | J38: 4 | K38: 4 | L38: 4 | M38: 4 | N38: 4 | O38: 4 | P38: 4 | Q38: - | R38: - | S38: - | T38: - | U38: -
A39: Auxiliar de Engenharia | B39: 2 | C39: 2 | D39: 2 | E39: 2 | F39: 2 | G39: 2 | H39: 2 | I39: 2 | J39: 2 | K39: 2 | L39: 2 | M39: 2 | N39: 2 | O39: 2 | P39: 2 | Q39: - | R39: - | S39: - | T39: - | U39: -
A40: Cadista | B40: 4 | C40: 4 | D40: 4 | E40: 4 | F40: 4 | G40: 4 | H40: 4 | I40: 4 | J40: 4 | K40: 4 | L40: 4 | M40: 4 | N40: 4 | O40: 4 | P40: 4 | Q40: - | R40: - | S40: - | T40: - | U40: -
A41: Ger_Contratos | B41: Capacidade de analisar e identificar critérios, padrões e doc. referência. | C41: Análise Proj. Básico Civil | D41: Análise Proj. Básico Eletromecânico | E41: Análise Proj. Básico de MPCC | F41: Análise Proj. Básico de Serv. Aux. | G41: Análise Proj. Executivo Civil | H41: Análise Proj. Executivo Eletromecânico | I41: Análise Proj. Executivo de MPCC | J41: Análise Projeto de Equipamentos | K41: Levantamento de Campo | L41: Acompanhamento Obras Civis, Montagem Eletromecânico e Elétrico | M41: Acompanhamento Comissionamento e Posta em Marcha | N41: - | O41: - | P41: - | Q41: - | R41: - | S41: - | T41: - | U41: -
A43: Gerente de Contratos | B43: 5 | C43: 5 | D43: 5 | E43: 5 | F43: 5 | G43: 5 | H43: 5 | I43: 5 | J43: 5 | K43: 5 | L43: 5 | M43: 5 | N43: - | O43: - | P43: - | Q43: - | R43: - | S43: - | T43: - | U43: -
A44: Adm_Financeiro | B44: Domínio de softwares da área. | C44: Pacote Office (Excel avançado, desejável). | D44: Pacote Office, especialmente Excel avançado. | E44: Finanças e contabilidade básica. | F44: Legislação tributária básica, desejável. | G44: ERP (Totvs, Oracle, etc.), desejável | H44: Processos financeiros (controle de custos, contas a pagar, contas a receber, fluxo de caixa, faturamento, controles financeiros, conciliação bancária, etc). | I44: Controle de custos. | J44: Adiantamentos e fechamento de prestação de contas de viagem. | K44: Controle de frota de veículos. | L44: Sistema de compras e controle de estoques. | M44: Rotinas gerais de contabilidade, conciliação bancária, relatórios gerenciais, lançamentos e classificações. | N44: Controle de custos e financeiro. | O44: Entendimento de análise de dados e de previsão. | P44: Microsoft Power BI. | Q44: Linguagem Python. | R44: Entendimento das rotinas e procedimentos de RH. | S44: Desenvolvimento de métricas e relatórios. | T44: Conhecimento de leis trabalhistas, desejável. | U44: -
...

Sheet Roteiro
A1: ETAPAS DO PDI
A2: Reunião, por área, para explicar os passos do PDI
A3: Gerente de área envia e-mail para o colaborador contendo as Avaliações Soft Skills e Hard Skills em PDF, convidando para a reunião inicial do PDI 2024.
A4: Realizar a reunião com o colaborador para discussão do resultado das Auto-Avaliações e Avaliações do Gerente.
